Workbook

Sheet Tat ca de tai
A1: STT | B1: Lĩnh vực | C1: Mã đề tài | D1: Tên đề tài | E1: Nền tảng gợi ý | F1: Mô tả ngắn | G1: Module/chức năng chính | H1: Phân công nhóm 5 SV (vai trò) | I1: Độ khó | J1: Gợi ý AI/ML mở rộng | K1: Phạm vi MVP 8 tuần | L1: Hồ sơ QLDA bắt buộc | M1: Mốc nghiệm thu | N1: Điều kiện đạt | O1: Nhóm đăng ký (GV nhập) | P1: Trạng thái
A2: 1 | B2: Bán lẻ | C2: LV01-001 | D2: Hệ thống quản lý tổng thể cho cửa hàng bán lẻ | E2: Mobile App | F2: Đồ án 8 tuần cho nhóm 5 SV: xây dựng Mobile App phục vụ cửa hàng bán lẻ; quản lý các thực thể chính: sản phẩm, khách hàng, đơn hàng, kho, hóa đơn; có CSDL, API, giao diện người dùng, báo cáo và kiểm thử. | G2: Đăng nhập phân quyền, CRUD, tìm kiếm/lọc, dashboard thống kê, import/export, báo cáo PDF/Excel, kiểm thử; nghiệp vụ trọng tâm: quản lý tổng thể; AI/ML gợi ý: dự báo tồn kho. | H2: ='Huong dan giao do an'!$B$14 -> 5 SV (vai trò chính): 1 PM/Scrum Master kiêm Integration; 2 BA/PO; 3 UI-UX + Frontend; 4 Backend/API + DevOps; 5 Database + QA/Tester. Mỗi SV có nhiệm vụ phụ và minh chứng cá nhân. | I2: Khá | J2: dự báo tồn kho | K2: =IF(I2="Trung bình",'Huong dan giao do an'!$B$8,IF(I2="Khá",'Huong dan giao do an'!$B$9,'Huong dan giao do an'!$B$10)) -> Tối thiểu 4 actor; 10-14 use case; 8-12 bảng; 3 quy trình lõi; phân quyền chi tiết; 2 báo cáo; tích hợp 1 dịch vụ; >=35 test case; CI/CD hoặc deploy cloud. | L2: ='Huong dan giao do an'!$B$31 -> Bắt buộc: Charter/PMP; SRS + scope/WBS; Gantt/baseline; effort-cost budget; RACI/timesheet; quality-test-defect; communication/minutes; risk register; procurement; change log; closure/lessons learned. | M2: ='Huong dan giao do an'!$B$33 -> Tuần 1: 07.09–13.09.2026; Tuần 2: 14.09–20.09.2026; Tuần 3: 21.09–27.09.2026; Tuần 4: 28.09–04.10.2026; Tuần 5: 05.10–11.10.2026; Tuần 6: 12.10–18.10.2026; Tuần 7: 19.10–25.10.2026; Tuần 8: 26.10–01.11.2026. | N2: ='Huong dan giao do an'!$B$53 -> Bắt buộc: đề tài được duyệt; sản phẩm chạy end-to-end; >=80% phạm vi baseline và 100% chức năng Must-have; đủ hồ sơ QLDA; test pass >=90%; không còn lỗi Critical/High; repo có đóng góp của 5 SV; mỗi SV vượt qua vấn đáp. | P2: =IF(O2="","Còn trống","Đã đăng ký") -> Còn trống
A3: 2 | B3: Bán lẻ | C3: LV01-002 | D3: Hệ thống đặt lịch/đặt chỗ cho cửa hàng bán lẻ | E3: Desktop App | F3: Đồ án 8 tuần cho nhóm 5 SV: xây dựng Desktop App phục vụ cửa hàng bán lẻ; quản lý các thực thể chính: sản phẩm, khách hàng, đơn hàng, kho, hóa đơn; có CSDL, API, giao diện người dùng, báo cáo và kiểm thử. | G3: Đăng nhập phân quyền, CRUD, tìm kiếm/lọc, dashboard thống kê, import/export, báo cáo PDF/Excel, kiểm thử; nghiệp vụ trọng tâm: đặt lịch/đặt chỗ; AI/ML gợi ý: phân nhóm khách hàng. | H3: ='Huong dan giao do an'!$B$14 -> 5 SV (vai trò chính): 1 PM/Scrum Master kiêm Integration; 2 BA/PO; 3 UI-UX + Frontend; 4 Backend/API + DevOps; 5 Database + QA/Tester. Mỗi SV có nhiệm vụ phụ và minh chứng cá nhân. | I3: Khó | J3: phân nhóm khách hàng | K3: =IF(I3="Trung bình",'Huong dan giao do an'!$B$8,IF(I3="Khá",'Huong dan giao do an'!$B$9,'Huong dan giao do an'!$B$10)) -> Tối thiểu 5 actor; 14-18 use case; 10-15 bảng; 4 quy trình; tích hợp ngoài/realtime hoặc xử lý nâng cao; 3 báo cáo; >=45 test case; logging, backup và deploy. | L3: ='Huong dan giao do an'!$B$31 -> Bắt buộc: Charter/PMP; SRS + scope/WBS; Gantt/baseline; effort-cost budget; RACI/timesheet; quality-test-defect; communication/minutes; risk register; procurement; change log; closure/lessons learned. | M3: ='Huong dan giao do an'!$B$33 -> Tuần 1: 07.09–13.09.2026; Tuần 2: 14.09–20.09.2026; Tuần 3: 21.09–27.09.2026; Tuần 4: 28.09–04.10.2026; Tuần 5: 05.10–11.10.2026; Tuần 6: 12.10–18.10.2026; Tuần 7: 19.10–25.10.2026; Tuần 8: 26.10–01.11.2026. | N3: ='Huong dan giao do an'!$B$53 -> Bắt buộc: đề tài được duyệt; sản phẩm chạy end-to-end; >=80% phạm vi baseline và 100% chức năng Must-have; đủ hồ sơ QLDA; test pass >=90%; không còn lỗi Critical/High; repo có đóng góp của 5 SV; mỗi SV vượt qua vấn đáp. | P3: =IF(O3="","Còn trống","Đã đăng ký") -> Còn trống
A4: 3 | B4: Bán lẻ | C4: LV01-003 | D4: Hệ thống bán hàng và thanh toán cho cửa hàng bán lẻ | E4: Web + Mobile | F4: Đồ án 8 tuần cho nhóm 5 SV: xây dựng Web + Mobile phục vụ cửa hàng bán lẻ; quản lý các thực thể chính: sản phẩm, khách hàng, đơn hàng, kho, hóa đơn; có CSDL, API, giao diện người dùng, báo cáo và kiểm thử. | G4: Đăng nhập phân quyền, CRUD, tìm kiếm/lọc, dashboard thống kê, import/export, báo cáo PDF/Excel, kiểm thử; nghiệp vụ trọng tâm: bán hàng và thanh toán; AI/ML gợi ý: gợi ý sản phẩm. | H4: ='Huong dan giao do an'!$B$14 -> 5 SV (vai trò chính): 1 PM/Scrum Master kiêm Integration; 2 BA/PO; 3 UI-UX + Frontend; 4 Backend/API + DevOps; 5 Database + QA/Tester. Mỗi SV có nhiệm vụ phụ và minh chứng cá nhân. | I4: Trung bình | J4: gợi ý sản phẩm | K4: =IF(I4="Trung bình",'Huong dan giao do an'!$B$8,IF(I4="Khá",'Huong dan giao do an'!$B$9,'Huong dan giao do an'!$B$10)) -> Tối thiểu 3 actor; 8-10 use case; 6-8 bảng dữ liệu; 2 quy trình lõi; đăng nhập/RBAC; 1 dashboard; 1 báo cáo; >=25 test case; triển khai bản demo. | L4: ='Huong dan giao do an'!$B$31 -> Bắt buộc: Charter/PMP; SRS + scope/WBS; Gantt/baseline; effort-cost budget; RACI/timesheet; quality-test-defect; communication/minutes; risk register; procurement; change log; closure/lessons learned. | M4: ='Huong dan giao do an'!$B$33 -> Tuần 1: 07.09–13.09.2026; Tuần 2: 14.09–20.09.2026; Tuần 3: 21.09–27.09.2026; Tuần 4: 28.09–04.10.2026; Tuần 5: 05.10–11.10.2026; Tuần 6: 12.10–18.10.2026; Tuần 7: 19.10–25.10.2026; Tuần 8: 26.10–01.11.2026. | N4: ='Huong dan giao do an'!$B$53 -> Bắt buộc: đề tài được duyệt; sản phẩm chạy end-to-end; >=80% phạm vi baseline và 100% chức năng Must-have; đủ hồ sơ QLDA; test pass >=90%; không còn lỗi Critical/High; repo có đóng góp của 5 SV; mỗi SV vượt qua vấn đáp. | P4: =IF(O4="","Còn trống","Đã đăng ký") -> Còn trống
A5: 4 | B5: Bán lẻ | C5: LV01-004 | D5: Hệ thống quản lý khách hàng CRM cho cửa hàng bán lẻ | E5: Web + Desktop | F5: Đồ án 8 tuần cho nhóm 5 SV: xây dựng Web + Desktop phục vụ cửa hàng bán lẻ; quản lý các thực thể chính: sản phẩm, khách hàng, đơn hàng, kho, hóa đơn; có CSDL, API, giao diện người dùng, báo cáo và kiểm thử. | G5: Đăng nhập phân quyền, CRUD, tìm kiếm/lọc, dashboard thống kê, import/export, báo cáo PDF/Excel, kiểm thử; nghiệp vụ trọng tâm: quản lý khách hàng CRM; AI/ML gợi ý: dự báo tồn kho. | H5: ='Huong dan giao do an'!$B$14 -> 5 SV (vai trò chính): 1 PM/Scrum Master kiêm Integration; 2 BA/PO; 3 UI-UX + Frontend; 4 Backend/API + DevOps; 5 Database + QA/Tester. Mỗi SV có nhiệm vụ phụ và minh chứng cá nhân. | I5: Khá | J5: dự báo tồn kho | K5: =IF(I5="Trung bình",'Huong dan giao do an'!$B$8,IF(I5="Khá",'Huong dan giao do an'!$B$9,'Huong dan giao do an'!$B$10)) -> Tối thiểu 4 actor; 10-14 use case; 8-12 bảng; 3 quy trình lõi; phân quyền chi tiết; 2 báo cáo; tích hợp 1 dịch vụ; >=35 test case; CI/CD hoặc deploy cloud. | L5: ='Huong dan giao do an'!$B$31 -> Bắt buộc: Charter/PMP; SRS + scope/WBS; Gantt/baseline; effort-cost budget; RACI/timesheet; quality-test-defect; communication/minutes; risk register; procurement; change log; closure/lessons learned. | M5: ='Huong dan giao do an'!$B$33 -> Tuần 1: 07.09–13.09.2026; Tuần 2: 14.09–20.09.2026; Tuần 3: 21.09–27.09.2026; Tuần 4: 28.09–04.10.2026; Tuần 5: 05.10–11.10.2026; Tuần 6: 12.10–18.10.2026; Tuần 7: 19.10–25.10.2026; Tuần 8: 26.10–01.11.2026. | N5: ='Huong dan giao do an'!$B$53 -> Bắt buộc: đề tài được duyệt; sản phẩm chạy end-to-end; >=80% phạm vi baseline và 100% chức năng Must-have; đủ hồ sơ QLDA; test pass >=90%; không còn lỗi Critical/High; repo có đóng góp của 5 SV; mỗi SV vượt qua vấn đáp. | P5: =IF(O5="","Còn trống","Đã đăng ký") -> Còn trống
A6: 5 | B6: Bán lẻ | C6: LV01-005 | D6: Hệ thống quản lý kho/tài sản cho cửa hàng bán lẻ | E6: Website | F6: Đồ án 8 tuần cho nhóm 5 SV: xây dựng Website phục vụ cửa hàng bán lẻ; quản lý các thực thể chính: sản phẩm, khách hàng, đơn hàng, kho, hóa đơn; có CSDL, API, giao diện người dùng, báo cáo và kiểm thử. | G6: Đăng nhập phân quyền, CRUD, tìm kiếm/lọc, dashboard thống kê, import/export, báo cáo PDF/Excel, kiểm thử; nghiệp vụ trọng tâm: quản lý kho/tài sản; AI/ML gợi ý: phân nhóm khách hàng. | H6: ='Huong dan giao do an'!$B$14 -> 5 SV (vai trò chính): 1 PM/Scrum Master kiêm Integration; 2 BA/PO; 3 UI-UX + Frontend; 4 Backend/API + DevOps; 5 Database + QA/Tester. Mỗi SV có nhiệm vụ phụ và minh chứng cá nhân. | I6: Khó | J6: phân nhóm khách hàng | K6: =IF(I6="Trung bình",'Huong dan giao do an'!$B$8,IF(I6="Khá",'Huong dan giao do an'!$B$9,'Huong dan giao do an'!$B$10)) -> Tối thiểu 5 actor; 14-18 use case; 10-15 bảng; 4 quy trình; tích hợp ngoài/realtime hoặc xử lý nâng cao; 3 báo cáo; >=45 test case; logging, backup và deploy. | L6: ='Huong dan giao do an'!$B$31 -> Bắt buộc: Charter/PMP; SRS + scope/WBS; Gantt/baseline; effort-cost budget; RACI/timesheet; quality-test-defect; communication/minutes; risk register; procurement; change log; closure/lessons learned. | M6: ='Huong dan giao do an'!$B$33 -> Tuần 1: 07.09–13.09.2026; Tuần 2: 14.09–20.09.2026; Tuần 3: 21.09–27.09.2026; Tuần 4: 28.09–04.10.2026; Tuần 5: 05.10–11.10.2026; Tuần 6: 12.10–18.10.2026; Tuần 7: 19.10–25.10.2026; Tuần 8: 26.10–01.11.2026. | N6: ='Huong dan giao do an'!$B$53 -> Bắt buộc: đề tài được duyệt; sản phẩm chạy end-to-end; >=80% phạm vi baseline và 100% chức năng Must-have; đủ hồ sơ QLDA; test pass >=90%; không còn lỗi Critical/High; repo có đóng góp của 5 SV; mỗi SV vượt qua vấn đáp. | P6: =IF(O6="","Còn trống","Đã đăng ký") -> Còn trống
A7: 6 | B7: Bán lẻ | C7: LV01-006 | D7: Hệ thống quản lý nhân sự và ca làm cho cửa hàng bán lẻ | E7: Mobile App | F7: Đồ án 8 tuần cho nhóm 5 SV: xây dựng Mobile App phục vụ cửa hàng bán lẻ; quản lý các thực thể chính: sản phẩm, khách hàng, đơn hàng, kho, hóa đơn; có CSDL, API, giao diện người dùng, báo cáo và kiểm thử. | G7: Đăng nhập phân quyền, CRUD, tìm kiếm/lọc, dashboard thống kê, import/export, báo cáo PDF/Excel, kiểm thử; nghiệp vụ trọng tâm: quản lý nhân sự và ca làm; AI/ML gợi ý: gợi ý sản phẩm. | H7: ='Huong dan giao do an'!$B$14 -> 5 SV (vai trò chính): 1 PM/Scrum Master kiêm Integration; 2 BA/PO; 3 UI-UX + Frontend; 4 Backend/API + DevOps; 5 Database + QA/Tester. Mỗi SV có nhiệm vụ phụ và minh chứng cá nhân. | I7: Trung bình | J7: gợi ý sản phẩm | K7: =IF(I7="Trung bình",'Huong dan giao do an'!$B$8,IF(I7="Khá",'Huong dan giao do an'!$B$9,'Huong dan giao do an'!$B$10)) -> Tối thiểu 3 actor; 8-10 use case; 6-8 bảng dữ liệu; 2 quy trình lõi; đăng nhập/RBAC; 1 dashboard; 1 báo cáo; >=25 test case; triển khai bản demo. | L7: ='Huong dan giao do an'!$B$31 -> Bắt buộc: Charter/PMP; SRS + scope/WBS; Gantt/baseline; effort-cost budget; RACI/timesheet; quality-test-defect; communication/minutes; risk register; procurement; change log; closure/lessons learned. | M7: ='Huong dan giao do an'!$B$33 -> Tuần 1: 07.09–13.09.2026; Tuần 2: 14.09–20.09.2026; Tuần 3: 21.09–27.09.2026; Tuần 4: 28.09–04.10.2026; Tuần 5: 05.10–11.10.2026; Tuần 6: 12.10–18.10.2026; Tuần 7: 19.10–25.10.2026; Tuần 8: 26.10–01.11.2026. | N7: ='Huong dan giao do an'!$B$53 -> Bắt buộc: đề tài được duyệt; sản phẩm chạy end-to-end; >=80% phạm vi baseline và 100% chức năng Must-have; đủ hồ sơ QLDA; test pass >=90%; không còn lỗi Critical/High; repo có đóng góp của 5 SV; mỗi SV vượt qua vấn đáp. | P7: =IF(O7="","Còn trống","Đã đăng ký") -> Còn trống
A8: 7 | B8: Bán lẻ | C8: LV01-007 | D8: Hệ thống quản lý hóa đơn/công nợ cho cửa hàng bán lẻ | E8: Desktop App | F8: Đồ án 8 tuần cho nhóm 5 SV: xây dựng Desktop App phục vụ cửa hàng bán lẻ; quản lý các thực thể chính: sản phẩm, khách hàng, đơn hàng, kho, hóa đơn; có CSDL, API, giao diện người dùng, báo cáo và kiểm thử. | G8: Đăng nhập phân quyền, CRUD, tìm kiếm/lọc, dashboard thống kê, import/export, báo cáo PDF/Excel, kiểm thử; nghiệp vụ trọng tâm: quản lý hóa đơn/công nợ; AI/ML gợi ý: dự báo tồn kho. | H8: ='Huong dan giao do an'!$B$14 -> 5 SV (vai trò chính): 1 PM/Scrum Master kiêm Integration; 2 BA/PO; 3 UI-UX + Frontend; 4 Backend/API + DevOps; 5 Database + QA/Tester. Mỗi SV có nhiệm vụ phụ và minh chứng cá nhân. | I8: Khá | J8: dự báo tồn kho | K8: =IF(I8="Trung bình",'Huong dan giao do an'!$B$8,IF(I8="Khá",'Huong dan giao do an'!$B$9,'Huong dan giao do an'!$B$10)) -> Tối thiểu 4 actor; 10-14 use case; 8-12 bảng; 3 quy trình lõi; phân quyền chi tiết; 2 báo cáo; tích hợp 1 dịch vụ; >=35 test case; CI/CD hoặc deploy cloud. | L8: ='Huong dan giao do an'!$B$31 -> Bắt buộc: Charter/PMP; SRS + scope/WBS; Gantt/baseline; effort-cost budget; RACI/timesheet; quality-test-defect; communication/minutes; risk register; procurement; change log; closure/lessons learned. | M8: ='Huong dan giao do an'!$B$33 -> Tuần 1: 07.09–13.09.2026; Tuần 2: 14.09–20.09.2026; Tuần 3: 21.09–27.09.2026; Tuần 4: 28.09–04.10.2026; Tuần 5: 05.10–11.10.2026; Tuần 6: 12.10–18.10.2026; Tuần 7: 19.10–25.10.2026; Tuần 8: 26.10–01.11.2026. | N8: ='Huong dan giao do an'!$B$53 -> Bắt buộc: đề tài được duyệt; sản phẩm chạy end-to-end; >=80% phạm vi baseline và 100% chức năng Must-have; đủ hồ sơ QLDA; test pass >=90%; không còn lỗi Critical/High; repo có đóng góp của 5 SV; mỗi SV vượt qua vấn đáp. | P8: =IF(O8="","Còn trống","Đã đăng ký") -> Còn trống
A9: 8 | B9: Bán lẻ | C9: LV01-008 | D9: Hệ thống báo cáo thống kê doanh thu cho cửa hàng bán lẻ | E9: Web + Mobile | F9: Đồ án 8 tuần cho nhóm 5 SV: xây dựng Web + Mobile phục vụ cửa hàng bán lẻ; quản lý các thực thể chính: sản phẩm, khách hàng, đơn hàng, kho, hóa đơn; có CSDL, API, giao diện người dùng, báo cáo và kiểm thử. | G9: Đăng nhập phân quyền, CRUD, tìm kiếm/lọc, dashboard thống kê, import/export, báo cáo PDF/Excel, kiểm thử; nghiệp vụ trọng tâm: báo cáo thống kê doanh thu; AI/ML gợi ý: phân nhóm khách hàng. | H9: ='Huong dan giao do an'!$B$14 -> 5 SV (vai trò chính): 1 PM/Scrum Master kiêm Integration; 2 BA/PO; 3 UI-UX + Frontend; 4 Backend/API + DevOps; 5 Database + QA/Tester. Mỗi SV có nhiệm vụ phụ và minh chứng cá nhân. | I9: Khó | J9: phân nhóm khách hàng | K9: =IF(I9="Trung bình",'Huong dan giao do an'!$B$8,IF(I9="Khá",'Huong dan giao do an'!$B$9,'Huong dan giao do an'!$B$10)) -> Tối thiểu 5 actor; 14-18 use case; 10-15 bảng; 4 quy trình; tích hợp ngoài/realtime hoặc xử lý nâng cao; 3 báo cáo; >=45 test case; logging, backup và deploy. | L9: ='Huong dan giao do an'!$B$31 -> Bắt buộc: Charter/PMP; SRS + scope/WBS; Gantt/baseline; effort-cost budget; RACI/timesheet; quality-test-defect; communication/minutes; risk register; procurement; change log; closure/lessons learned. | M9: ='Huong dan giao do an'!$B$33 -> Tuần 1: 07.09–13.09.2026; Tuần 2: 14.09–20.09.2026; Tuần 3: 21.09–27.09.2026; Tuần 4: 28.09–04.10.2026; Tuần 5: 05.10–11.10.2026; Tuần 6: 12.10–18.10.2026; Tuần 7: 19.10–25.10.2026; Tuần 8: 26.10–01.11.2026. | N9: ='Huong dan giao do an'!$B$53 -> Bắt buộc: đề tài được duyệt; sản phẩm chạy end-to-end; >=80% phạm vi baseline và 100% chức năng Must-have; đủ hồ sơ QLDA; test pass >=90%; không còn lỗi Critical/High; repo có đóng góp của 5 SV; mỗi SV vượt qua vấn đáp. | P9: =IF(O9="","Còn trống","Đã đăng ký") -> Còn trống
A10: 9 | B10: Bán lẻ | C10: LV01-009 | D10: Hệ thống cổng chăm sóc khách hàng cho cửa hàng bán lẻ | E10: Web + Desktop | F10: Đồ án 8 tuần cho nhóm 5 SV: xây dựng Web + Desktop phục vụ cửa hàng bán lẻ; quản lý các thực thể chính: sản phẩm, khách hàng, đơn hàng, kho, hóa đơn; có CSDL, API, giao diện người dùng, báo cáo và kiểm thử. | G10: Đăng nhập phân quyền, CRUD, tìm kiếm/lọc, dashboard thống kê, import/export, báo cáo PDF/Excel, kiểm thử; nghiệp vụ trọng tâm: cổng chăm sóc khách hàng; AI/ML gợi ý: gợi ý sản phẩm. | H10: ='Huong dan giao do an'!$B$14 -> 5 SV (vai trò chính): 1 PM/Scrum Master kiêm Integration; 2 BA/PO; 3 UI-UX + Frontend; 4 Backend/API + DevOps; 5 Database + QA/Tester. Mỗi SV có nhiệm vụ phụ và minh chứng cá nhân. | I10: Trung bình | J10: gợi ý sản phẩm | K10: =IF(I10="Trung bình",'Huong dan giao do an'!$B$8,IF(I10="Khá",'Huong dan giao do an'!$B$9,'Huong dan giao do an'!$B$10)) -> Tối thiểu 3 actor; 8-10 use case; 6-8 bảng dữ liệu; 2 quy trình lõi; đăng nhập/RBAC; 1 dashboard; 1 báo cáo; >=25 test case; triển khai bản demo. | L10: ='Huong dan giao do an'!$B$31 -> Bắt buộc: Charter/PMP; SRS + scope/WBS; Gantt/baseline; effort-cost budget; RACI/timesheet; quality-test-defect; communication/minutes; risk register; procurement; change log; closure/lessons learned. | M10: ='Huong dan giao do an'!$B$33 -> Tuần 1: 07.09–13.09.2026; Tuần 2: 14.09–20.09.2026; Tuần 3: 21.09–27.09.2026; Tuần 4: 28.09–04.10.2026; Tuần 5: 05.10–11.10.2026; Tuần 6: 12.10–18.10.2026; Tuần 7: 19.10–25.10.2026; Tuần 8: 26.10–01.11.2026. | N10: ='Huong dan giao do an'!$B$53 -> Bắt buộc: đề tài được duyệt; sản phẩm chạy end-to-end; >=80% phạm vi baseline và 100% chức năng Must-have; đủ hồ sơ QLDA; test pass >=90%; không còn lỗi Critical/High; repo có đóng góp của 5 SV; mỗi SV vượt qua vấn đáp. | P10: =IF(O10="","Còn trống","Đã đăng ký") -> Còn trống
A11: 10 | B11: Bán lẻ | C11: LV01-010 | D11: Hệ thống ứng dụng loyalty/tích điểm cho cửa hàng bán lẻ | E11: Website | F11: Đồ án 8 tuần cho nhóm 5 SV: xây dựng Website phục vụ cửa hàng bán lẻ; quản lý các thực thể chính: sản phẩm, khách hàng, đơn hàng, kho, hóa đơn; có CSDL, API, giao diện người dùng, báo cáo và kiểm thử. | G11: Đăng nhập phân quyền, CRUD, tìm kiếm/lọc, dashboard thống kê, import/export, báo cáo PDF/Excel, kiểm thử; nghiệp vụ trọng tâm: ứng dụng loyalty/tích điểm; AI/ML gợi ý: dự báo tồn kho. | H11: ='Huong dan giao do an'!$B$14 -> 5 SV (vai trò chính): 1 PM/Scrum Master kiêm Integration; 2 BA/PO; 3 UI-UX + Frontend; 4 Backend/API + DevOps; 5 Database + QA/Tester. Mỗi SV có nhiệm vụ phụ và minh chứng cá nhân. | I11: Khá | J11: dự báo tồn kho | K11: =IF(I11="Trung bình",'Huong dan giao do an'!$B$8,IF(I11="Khá",'Huong dan giao do an'!$B$9,'Huong dan giao do an'!$B$10)) -> Tối thiểu 4 actor; 10-14 use case; 8-12 bảng; 3 quy trình lõi; phân quyền chi tiết; 2 báo cáo; tích hợp 1 dịch vụ; >=35 test case; CI/CD hoặc deploy cloud. | L11: ='Huong dan giao do an'!$B$31 -> Bắt buộc: Charter/PMP; SRS + scope/WBS; Gantt/baseline; effort-cost budget; RACI/timesheet; quality-test-defect; communication/minutes; risk register; procurement; change log; closure/lessons learned. | M11: ='Huong dan giao do an'!$B$33 -> Tuần 1: 07.09–13.09.2026; Tuần 2: 14.09–20.09.2026; Tuần 3: 21.09–27.09.2026; Tuần 4: 28.09–04.10.2026; Tuần 5: 05.10–11.10.2026; Tuần 6: 12.10–18.10.2026; Tuần 7: 19.10–25.10.2026; Tuần 8: 26.10–01.11.2026. | N11: ='Huong dan giao do an'!$B$53 -> Bắt buộc: đề tài được duyệt; sản phẩm chạy end-to-end; >=80% phạm vi baseline và 100% chức năng Must-have; đủ hồ sơ QLDA; test pass >=90%; không còn lỗi Critical/High; repo có đóng góp của 5 SV; mỗi SV vượt qua vấn đáp. | P11: =IF(O11="","Còn trống","Đã đăng ký") -> Còn trống
A12: 11 | B12: Bán lẻ | C12: LV01-011 | D12: Hệ thống quản lý quy trình nghiệp vụ cho cửa hàng bán lẻ | E12: Mobile App | F12: Đồ án 8 tuần cho nhóm 5 SV: xây dựng Mobile App phục vụ cửa hàng bán lẻ; quản lý các thực thể chính: sản phẩm, khách hàng, đơn hàng, kho, hóa đơn; có CSDL, API, giao diện người dùng, báo cáo và kiểm thử. | G12: Đăng nhập phân quyền, CRUD, tìm kiếm/lọc, dashboard thống kê, import/export, báo cáo PDF/Excel, kiểm thử; nghiệp vụ trọng tâm: quản lý quy trình nghiệp vụ; AI/ML gợi ý: phân nhóm khách hàng. | H12: ='Huong dan giao do an'!$B$14 -> 5 SV (vai trò chính): 1 PM/Scrum Master kiêm Integration; 2 BA/PO; 3 UI-UX + Frontend; 4 Backend/API + DevOps; 5 Database + QA/Tester. Mỗi SV có nhiệm vụ phụ và minh chứng cá nhân. | I12: Khó | J12: phân nhóm khách hàng | K12: =IF(I12="Trung bình",'Huong dan giao do an'!$B$8,IF(I12="Khá",'Huong dan giao do an'!$B$9,'Huong dan giao do an'!$B$10)) -> Tối thiểu 5 actor; 14-18 use case; 10-15 bảng; 4 quy trình; tích hợp ngoài/realtime hoặc xử lý nâng cao; 3 báo cáo; >=45 test case; logging, backup và deploy. | L12: ='Huong dan giao do an'!$B$31 -> Bắt buộc: Charter/PMP; SRS + scope/WBS; Gantt/baseline; effort-cost budget; RACI/timesheet; quality-test-defect; communication/minutes; risk register; procurement; change log; closure/lessons learned. | M12: ='Huong dan giao do an'!$B$33 -> Tuần 1: 07.09–13.09.2026; Tuần 2: 14.09–20.09.2026; Tuần 3: 21.09–27.09.2026; Tuần 4: 28.09–04.10.2026; Tuần 5: 05.10–11.10.2026; Tuần 6: 12.10–18.10.2026; Tuần 7: 19.10–25.10.2026; Tuần 8: 26.10–01.11.2026. | N12: ='Huong dan giao do an'!$B$53 -> Bắt buộc: đề tài được duyệt; sản phẩm chạy end-to-end; >=80% phạm vi baseline và 100% chức năng Must-have; đủ hồ sơ QLDA; test pass >=90%; không còn lỗi Critical/High; repo có đóng góp của 5 SV; mỗi SV vượt qua vấn đáp. | P12: =IF(O12="","Còn trống","Đã đăng ký") -> Còn trống
A13: 12 | B13: Bán lẻ | C13: LV01-012 | D13: Hệ thống theo dõi trạng thái thời gian thực cho cửa hàng bán lẻ | E13: Desktop App | F13: Đồ án 8 tuần cho nhóm 5 SV: xây dựng Desktop App phục vụ cửa hàng bán lẻ; quản lý các thực thể chính: sản phẩm, khách hàng, đơn hàng, kho, hóa đơn; có CSDL, API, giao diện người dùng, báo cáo và kiểm thử. | G13: Đăng nhập phân quyền, CRUD, tìm kiếm/lọc, dashboard thống kê, import/export, báo cáo PDF/Excel, kiểm thử; nghiệp vụ trọng tâm: theo dõi trạng thái thời gian thực; AI/ML gợi ý: gợi ý sản phẩm. | H13: ='Huong dan giao do an'!$B$14 -> 5 SV (vai trò chính): 1 PM/Scrum Master kiêm Integration; 2 BA/PO; 3 UI-UX + Frontend; 4 Backend/API + DevOps; 5 Database + QA/Tester. Mỗi SV có nhiệm vụ phụ và minh chứng cá nhân. | I13: Trung bình | J13: gợi ý sản phẩm | K13: =IF(I13="Trung bình",'Huong dan giao do an'!$B$8,IF(I13="Khá",'Huong dan giao do an'!$B$9,'Huong dan giao do an'!$B$10)) -> Tối thiểu 3 actor; 8-10 use case; 6-8 bảng dữ liệu; 2 quy trình lõi; đăng nhập/RBAC; 1 dashboard; 1 báo cáo; >=25 test case; triển khai bản demo. | L13: ='Huong dan giao do an'!$B$31 -> Bắt buộc: Charter/PMP; SRS + scope/WBS; Gantt/baseline; effort-cost budget; RACI/timesheet; quality-test-defect; communication/minutes; risk register; procurement; change log; closure/lessons learned. | M13: ='Huong dan giao do an'!$B$33 -> Tuần 1: 07.09–13.09.2026; Tuần 2: 14.09–20.09.2026; Tuần 3: 21.09–27.09.2026; Tuần 4: 28.09–04.10.2026; Tuần 5: 05.10–11.10.2026; Tuần 6: 12.10–18.10.2026; Tuần 7: 19.10–25.10.2026; Tuần 8: 26.10–01.11.2026. | N13: ='Huong dan giao do an'!$B$53 -> Bắt buộc: đề tài được duyệt; sản phẩm chạy end-to-end; >=80% phạm vi baseline và 100% chức năng Must-have; đủ hồ sơ QLDA; test pass >=90%; không còn lỗi Critical/High; repo có đóng góp của 5 SV; mỗi SV vượt qua vấn đáp. | P13: =IF(O13="","Còn trống","Đã đăng ký") -> Còn trống
... A3501: 3500 | B3501: Giải trí | C3501: LV35-100 | D3501: Hệ thống quản lý dữ liệu và import/export có gợi ý AI: phân tích đánh giá cho dịch vụ giải trí | E3501: Web + Desktop | F3501: Đồ án 8 tuần cho nhóm 5 SV: xây dựng Web + Desktop phục vụ dịch vụ giải trí; quản lý các thực thể chính: vé, phòng, suất chiếu/sự kiện, khách hàng; có CSDL, API, giao diện người dùng, báo cáo và kiểm thử. | G3501: Đăng nhập phân quyền, CRUD, tìm kiếm/lọc, dashboard thống kê, import/export, báo cáo PDF/Excel, kiểm thử; nghiệp vụ trọng tâm: quản lý dữ liệu và import/export; AI/ML gợi ý: phân tích đánh giá. | H3501: ='Huong dan giao do an'!$B$14 -> 5 SV (vai trò chính): 1 PM/Scrum Master kiêm Integration; 2 BA/PO; 3 UI-UX + Frontend; 4 Backend/API + DevOps; 5 Database + QA/Tester. Mỗi SV có nhiệm vụ phụ và minh chứng cá nhân. | I3501: Khó | J3501: phân tích đánh giá | K3501: =IF(I3501="Trung bình",'Huong dan giao do an'!$B$8,IF(I3501="Khá",'Huong dan giao do an'!$B$9,'Huong dan giao do an'!$B$10)) -> Tối thiểu 5 actor; 14-18 use case; 10-15 bảng; 4 quy trình; tích hợp ngoài/realtime hoặc xử lý nâng cao; 3 báo cáo; >=45 test case; logging, backup và deploy. | L3501: ='Huong dan giao do an'!$B$31 -> Bắt buộc: Charter/PMP; SRS + scope/WBS; Gantt/baseline; effort-cost budget; RACI/timesheet; quality-test-defect; communication/minutes; risk register; procurement; change log; closure/lessons learned. | M3501: ='Huong dan giao do an'!$B$33 -> Tuần 1: 07.09–13.09.2026; Tuần 2: 14.09–20.09.2026; Tuần 3: 21.09–27.09.2026; Tuần 4: 28.09–04.10.2026; Tuần 5: 05.10–11.10.2026; Tuần 6: 12.10–18.10.2026; Tuần 7: 19.10–25.10.2026; Tuần 8: 26.10–01.11.2026. | N3501: ='Huong dan giao do an'!$B$53 -> Bắt buộc: đề tài được duyệt; sản phẩm chạy end-to-end; >=80% phạm vi baseline và 100% chức năng Must-have; đủ hồ sơ QLDA; test pass >=90%; không còn lỗi Critical/High; repo có đóng góp của 5 SV; mỗi SV vượt qua vấn đáp. | P3501: =IF(O3501="","Còn trống","Đã đăng ký") -> Còn trống

Sheet Tom tat 35 linh vuc
A1: BẢNG TỔNG HỢP 35 LĨNH VỰC × 100 ĐỀ TÀI = 3.500 ĐỀ TÀI | G1: THÔNG TIN TRIỂN KHAI ĐỒ ÁN 8 TUẦN
G2: Bắt đầu | H2: 07.09.2026 | I2: Kết thúc | J2: 01.11.2026
A3: STT | B3: Lĩnh vực | C3: Số đề tài | D3: Ghi chú triển khai | E3: Sản phẩm tối thiểu | G3: Số tuần | H3: 8 | I3: Số buổi | J3: 9
A4: 1 | B4: Bán lẻ | C4: =COUNTIF('Tat ca de tai'!B:B,B4) -> 100 | D4: Phù hợp triển khai Web/Mobile/Desktop cho cửa hàng bán lẻ | E4: Frontend, Backend/API, Database, phân quyền, thống kê, báo cáo, kiểm thử | G4: Quy mô nhóm | H4: 5 | I4: Tổng đề tài | J4: 3500
A5: 2 | B5: Siêu thị / cửa hàng tiện lợi | C5: =COUNTIF('Tat ca de tai'!B:B,B5) -> 100 | D5: Phù hợp triển khai Web/Mobile/Desktop cho siêu thị mini | E5: Frontend, Backend/API, Database, phân quyền, thống kê, báo cáo, kiểm thử | G5: Còn trống | H5: =COUNTIF('Tat ca de tai'!P:P,"Còn trống") -> 3500 | I5: Đã đăng ký | J5: =COUNTIF('Tat ca de tai'!P:P,"Đã đăng ký") -> 0
A6: 3 | B6: Nhà thuốc | C6: =COUNTIF('Tat ca de tai'!B:B,B6) -> 100 | D6: Phù hợp triển khai Web/Mobile/Desktop cho nhà thuốc | E6: Frontend, Backend/API, Database, phân quyền, thống kê, báo cáo, kiểm thử | G6: Chọn đề tài | H6: Nhập tên/mã nhóm tại cột O của sheet Tat ca de tai; trạng thái cập nhật tự động.
A7: 4 | B7: Phòng khám | C7: =COUNTIF('Tat ca de tai'!B:B,B7) -> 100 | D7: Phù hợp triển khai Web/Mobile/Desktop cho phòng khám | E7: Frontend, Backend/API, Database, phân quyền, thống kê, báo cáo, kiểm thử | G7: Nguyên tắc | H7: Mỗi nhóm 01 đề tài, không trùng trong lớp, GV duyệt phạm vi trước khi triển khai.
A8: 5 | B8: Bệnh viện | C8: =COUNTIF('Tat ca de tai'!B:B,B8) -> 100 | D8: Phù hợp triển khai Web/Mobile/Desktop cho bệnh viện | E8: Frontend, Backend/API, Database, phân quyền, thống kê, báo cáo, kiểm thử | G8: Mốc giữa kỳ | H8: 04.10.2026 - demo >=50% và thuyết trình nhóm
A9: 6 | B9: Nha khoa | C9: =COUNTIF('Tat ca de tai'!B:B,B9) -> 100 | D9: Phù hợp triển khai Web/Mobile/Desktop cho phòng khám nha khoa | E9: Frontend, Backend/API, Database, phân quyền, thống kê, báo cáo, kiểm thử | G9: Bảo vệ | H9: 26.10–01.11.2026 theo lịch giảng viên
A10: 7 | B10: Spa / thẩm mỹ viện | C10: =COUNTIF('Tat ca de tai'!B:B,B10) -> 100 | D10: Phù hợp triển khai Web/Mobile/Desktop cho spa | E10: Frontend, Backend/API, Database, phân quyền, thống kê, báo cáo, kiểm thử
A11: 8 | B11: Gym / yoga | C11: =COUNTIF('Tat ca de tai'!B:B,B11) -> 100 | D11: Phù hợp triển khai Web/Mobile/Desktop cho phòng gym/yoga | E11: Frontend, Backend/API, Database, phân quyền, thống kê, báo cáo, kiểm thử | G11: KIỂM TRA HOÀN THIỆN DỮ LIỆU | H11: Giá trị | I11: Kỳ vọng | J11: Kết quả
A12: 9 | B12: Nhà hàng | C12: =COUNTIF('Tat ca de tai'!B:B,B12) -> 100 | D12: Phù hợp triển khai Web/Mobile/Desktop cho nhà hàng | E12: Frontend, Backend/API, Database, phân quyền, thống kê, báo cáo, kiểm thử | G12: Tổng dòng đề tài | H12: =COUNTA('Tat ca de tai'!C2:C3501) -> 3500 | I12: 3500 | J12: =IF(H12=I12,"OK","KIỂM TRA") -> OK
A13: 10 | B13: Quán cà phê | C13: =COUNTIF('Tat ca de tai'!B:B,B13) -> 100 | D13: Phù hợp triển khai Web/Mobile/Desktop cho quán cà phê | E13: Frontend, Backend/API, Database, phân quyền, thống kê, báo cáo, kiểm thử | G13: Trống phân công vai trò | H13: =COUNTBLANK('Tat ca de tai'!H2:H3501) -> 0 | I13: 0 | J13: =IF(H13=I13,"OK","KIỂM TRA") -> OK
A14: 11 | B14: Giao đồ ăn | C14: =COUNTIF('Tat ca de tai'!B:B,B14) -> 100 | D14: Phù hợp triển khai Web/Mobile/Desktop cho dịch vụ giao đồ ăn | E14: Frontend, Backend/API, Database, phân quyền, thống kê, báo cáo, kiểm thử | G14: Trống phạm vi MVP | H14: =COUNTBLANK('Tat ca de tai'!K2:K3501) -> 0 | I14: 0 | J14: =IF(H14=I14,"OK","KIỂM TRA") -> OK
A15: 12 | B15: Khách sạn | C15: =COUNTIF('Tat ca de tai'!B:B,B15) -> 100 | D15: Phù hợp triển khai Web/Mobile/Desktop cho khách sạn | E15: Frontend, Backend/API, Database, phân quyền, thống kê, báo cáo, kiểm thử | G15: Trống hồ sơ QLDA | H15: =COUNTBLANK('Tat ca de tai'!L2:L3501) -> 0 | I15: 0 | J15: =IF(H15=I15,"OK","KIỂM TRA") -> OK
A16: 13 | B16: Du lịch | C16: =COUNTIF('Tat ca de tai'!B:B,B16) -> 100 | D16: Phù hợp triển khai Web/Mobile/Desktop cho công ty du lịch | E16: Frontend, Backend/API, Database, phân quyền, thống kê, báo cáo, kiểm thử | G16: Trống mốc nghiệm thu | H16: =COUNTBLANK('Tat ca de tai'!M2:M3501) -> 0 | I16: 0 | J16: =IF(H16=I16,"OK","KIỂM TRA") -> OK
A17: 14 | B17: Vé xe / vận tải | C17: =COUNTIF('Tat ca de tai'!B:B,B17) -> 100 | D17: Phù hợp triển khai Web/Mobile/Desktop cho hãng xe | E17: Frontend, Backend/API, Database, phân quyền, thống kê, báo cáo, kiểm thử | G17: Trống điều kiện đạt | H17: =COUNTBLANK('Tat ca de tai'!N2:N3501) -> 0 | I17: 0 | J17: =IF(H17=I17,"OK","KIỂM TRA") -> OK
A18: 15 | B18: Taxi / xe công nghệ | C18: =COUNTIF('Tat ca de tai'!B:B,B18) -> 100 | D18: Phù hợp triển khai Web/Mobile/Desktop cho dịch vụ đặt xe | E18: Frontend, Backend/API, Database, phân quyền, thống kê, báo cáo, kiểm thử | G18: Trống trạng thái | H18: =COUNTBLANK('Tat ca de tai'!P2:P3501) -> 0 | I18: 0 | J18: =IF(H18=I18,"OK","KIỂM TRA") -> OK
A19: 16 | B19: Logistics | C19: =COUNTIF('Tat ca de tai'!B:B,B19) -> 100 | D19: Phù hợp triển khai Web/Mobile/Desktop cho doanh nghiệp logistics | E19: Frontend, Backend/API, Database, phân quyền, thống kê, báo cáo, kiểm thử | G19: Lỗi công thức H:P | H19: {=SUMPRODUCT(--ISERROR('Tat ca de tai'!H2:P3501))} -> 0 | I19: 0 | J19: =IF(H19=I19,"OK","KIỂM TRA") -> OK
A20: 17 | B20: Kho hàng | C20: =COUNTIF('Tat ca de tai'!B:B,B20) -> 100 | D20: Phù hợp triển khai Web/Mobile/Desktop cho kho hàng | E20: Frontend, Backend/API, Database, phân quyền, thống kê, báo cáo, kiểm thử | G20: Tổng trạng thái đăng ký | H20: =H5+J5 -> 3500 | I20: 3500 | J20: =IF(H20=I20,"OK","KIỂM TRA") -> OK
A21: 18 | B21: Bất động sản | C21: =COUNTIF('Tat ca de tai'!B:B,B21) -> 100 | D21: Phù hợp triển khai Web/Mobile/Desktop cho sàn bất động sản | E21: Frontend, Backend/API, Database, phân quyền, thống kê, báo cáo, kiểm thử
A22: 19 | B22: Xây dựng | C22: =COUNTIF('Tat ca de tai'!B:B,B22) -> 100 | D22: Phù hợp triển khai Web/Mobile/Desktop cho công ty xây dựng | E22: Frontend, Backend/API, Database, phân quyền, thống kê, báo cáo, kiểm thử
A23: 20 | B23: Giáo dục | C23: =COUNTIF('Tat ca de tai'!B:B,B23) -> 100 | D23: Phù hợp triển khai Web/Mobile/Desktop cho nền tảng giáo dục | E23: Frontend, Backend/API, Database, phân quyền, thống kê, báo cáo, kiểm thử
A24: 21 | B24: Trung tâm ngoại ngữ | C24: =COUNTIF('Tat ca de tai'!B:B,B24) -> 100 | D24: Phù hợp triển khai Web/Mobile/Desktop cho trung tâm ngoại ngữ | E24: Frontend, Backend/API, Database, phân quyền, thống kê, báo cáo, kiểm thử
A25: 22 | B25: Trường học | C25: =COUNTIF('Tat ca de tai'!B:B,B25) -> 100 | D25: Phù hợp triển khai Web/Mobile/Desktop cho trường học | E25: Frontend, Backend/API, Database, phân quyền, thống kê, báo cáo, kiểm thử
A26: 23 | B26: Thư viện | C26: =COUNTIF('Tat ca de tai'!B:B,B26) -> 100 | D26: Phù hợp triển khai Web/Mobile/Desktop cho thư viện | E26: Frontend, Backend/API, Database, phân quyền, thống kê, báo cáo, kiểm thử
A27: 24 | B27: Tuyển dụng | C27: =COUNTIF('Tat ca de tai'!B:B,B27) -> 100 | D27: Phù hợp triển khai Web/Mobile/Desktop cho nền tảng tuyển dụng | E27: Frontend, Backend/API, Database, phân quyền, thống kê, báo cáo, kiểm thử
A28: 25 | B28: Nhân sự | C28: =COUNTIF('Tat ca de tai'!B:B,B28) -> 100 | D28: Phù hợp triển khai Web/Mobile/Desktop cho phòng nhân sự | E28: Frontend, Backend/API, Database, phân quyền, thống kê, báo cáo, kiểm thử
A29: 26 | B29: Kế toán | C29: =COUNTIF('Tat ca de tai'!B:B,B29) -> 100 | D29: Phù hợp triển khai Web/Mobile/Desktop cho bộ phận kế toán | E29: Frontend, Backend/API, Database, phân quyền, thống kê, báo cáo, kiểm thử
A30: 27 | B30: Ngân hàng / tài chính | C30: =COUNTIF('Tat ca de tai'!B:B,B30) -> 100 | D30: Phù hợp triển khai Web/Mobile/Desktop cho dịch vụ tài chính | E30: Frontend, Backend/API, Database, phân quyền, thống kê, báo cáo, kiểm thử
A31: 28 | B31: Bảo hiểm | C31: =COUNTIF('Tat ca de tai'!B:B,B31) -> 100 | D31: Phù hợp triển khai Web/Mobile/Desktop cho công ty bảo hiểm | E31: Frontend, Backend/API, Database, phân quyền, thống kê, báo cáo, kiểm thử
A32: 29 | B32: Nông nghiệp | C32: =COUNTIF('Tat ca de tai'!B:B,B32) -> 100 | D32: Phù hợp triển khai Web/Mobile/Desktop cho trang trại trồng trọt | E32: Frontend, Backend/API, Database, phân quyền, thống kê, báo cáo, kiểm thử
... A38: 35 | B38: Giải trí | C38: =COUNTIF('Tat ca de tai'!B:B,B38) -> 100 | D38: Phù hợp triển khai Web/Mobile/Desktop cho dịch vụ giải trí | E38: Frontend, Backend/API, Database, phân quyền, thống kê, báo cáo, kiểm thử

Sheet Huong dan giao do an
A1: HƯỚNG DẪN VÀ YÊU CẦU ĐỒ ÁN QUẢN LÝ DỰ ÁN CNTT - 8 TUẦN
A2: Học phần | B2: MAN104 - Quản lý dự án công nghệ thông tin | C2: Thời gian | D2: 07.09.2026 - 01.11.2026 | E2: Quy mô | F2: Nhóm 5 SV; 8 tuần; 9 buổi
A3: Đối tượng | B3: SV năm 4 ngành CNTT, chuyên ngành Công nghệ phần mềm | C3: Căn cứ | D3: CLO2-CLO3; phạm vi, thời gian, chi phí, chất lượng, nhân sự, truyền thông, rủi ro, mua sắm, tích hợp | E3: Đánh giá | F3: Quá trình 50%; vấn đáp đồ án cuối kỳ 50%
A5: 1. ĐIỀU KIỆN CHỌN VÀ GIỚI HẠN ĐỀ TÀI
A6: Chọn đề tài | B6: Mỗi nhóm chọn 01 mã đề tài trong danh sách 3.500 đề tài; không trùng trong cùng lớp; chỉ được triển khai sau khi giảng viên duyệt phạm vi. | C6: Phiếu đăng ký: mã đề tài, tên nhóm, 5 thành viên, vai trò chính, công nghệ dự kiến | D6: Tuần 1 | E6: PM + BA/PO | F6: GV duyệt: phù hợp 8 tuần và có dữ liệu/nghiệp vụ khả thi
A7: Giới hạn phạm vi | B7: Ưu tiên MVP hoàn chỉnh thay vì nhiều chức năng dở dang. Chọn 2-4 quy trình nghiệp vụ lõi, có đầu vào, xử lý, trạng thái và đầu ra rõ ràng. | C7: Scope statement; in-scope/out-of-scope; tiêu chí chấp nhận; WBS | D7: Tuần 1 | E7: Cả nhóm | F7: Không chọn phạm vi cấp quốc gia, lõi ngân hàng, bệnh án thật hoặc dữ liệu nhạy cảm chưa ẩn danh
A8: Mức Trung bình | B8: Tối thiểu 3 actor; 8-10 use case; 6-8 bảng dữ liệu; 2 quy trình lõi; đăng nhập/RBAC; 1 dashboard; 1 báo cáo; >=25 test case; triển khai bản demo. | C8: SRS, ERD, prototype, source, test report, URL demo | D8: Tuần 8 | E8: Cả nhóm | F8: Phù hợp nhóm kỹ năng trung bình; ưu tiên chất lượng và hoàn thiện
A9: Mức Khá | B9: Tối thiểu 4 actor; 10-14 use case; 8-12 bảng; 3 quy trình lõi; phân quyền chi tiết; 2 báo cáo; tích hợp 1 dịch vụ; >=35 test case; CI/CD hoặc deploy cloud. | C9: SRS, ERD, API spec, source, test report, URL demo | D9: Tuần 8 | E9: Cả nhóm | F9: Có xử lý ngoại lệ, nhật ký thao tác và dữ liệu mẫu hợp lý
A10: Mức Khó | B10: Tối thiểu 5 actor; 14-18 use case; 10-15 bảng; 4 quy trình; tích hợp ngoài/realtime hoặc xử lý nâng cao; 3 báo cáo; >=45 test case; logging, backup và deploy. | C10: Hồ sơ kiến trúc, API/integration, source, test và vận hành | D10: Tuần 8 | E10: Cả nhóm | F10: Chỉ chọn khi nhóm chứng minh năng lực và kế hoạch giảm rủi ro
A11: Sản phẩm lõi | B11: Bắt buộc có Frontend, Backend/API, Database, xác thực, phân quyền, CRUD có kiểm tra dữ liệu, tìm kiếm/lọc, dashboard/báo cáo, kiểm thử và triển khai demo. | C11: Bản chạy được với dữ liệu mẫu; tài khoản demo theo vai trò | D11: Tuần 7-8 | E11: Dev team | F11: Không chấp nhận chỉ làm giao diện, prototype hoặc notebook rời rạc
A12: AI/ML mở rộng | B12: Chỉ là điểm cộng sau khi MVP đạt. Phải mô tả dữ liệu, cách đánh giá, giới hạn và không dùng AI để thay thế toàn bộ phân tích/thiết kế của nhóm. | C12: Dataset mẫu; mô tả mô hình; metric; màn hình tích hợp | D12: Tuần 7-8 | E12: Thành viên phụ trách | F12: Ứng dụng phù hợp nghiệp vụ, có giải thích kết quả
A13: 2. PHÂN CÔNG NHÓM 5 SINH VIÊN
A14: Mô hình vai trò | B14: 5 SV (vai trò chính): 1 PM/Scrum Master kiêm Integration; 2 BA/PO; 3 UI-UX + Frontend; 4 Backend/API + DevOps; 5 Database + QA/Tester. Mỗi SV có nhiệm vụ phụ và minh chứng cá nhân. | C14: RACI; backlog theo người; Git commits; issue/ticket; timesheet; biên bản họp | D14: Tuần 1-8 | E14: PM quản lý | F14: Không có thành viên chỉ đứng tên hoặc chỉ làm slide
A15: SV1 | B15: PM/Scrum Master + Integration: lập kế hoạch, WBS/Gantt, theo dõi tiến độ/chi phí, quản lý thay đổi, tích hợp và báo cáo tuần. | C15: Project plan; status report; change log; release checklist | D15: Hàng tuần | E15: SV1 | F15: Duy trì baseline và xử lý chênh lệch
A16: SV2 | B16: BA/PO: khảo sát, stakeholder, yêu cầu, user story/use case, acceptance criteria, ưu tiên backlog và nghiệm thu nghiệp vụ. | C16: SRS; backlog; use case; biên bản xác nhận yêu cầu | D16: Tuần 1-8 | E16: SV2 | F16: Yêu cầu truy vết được đến chức năng và test case
A17: SV3 | B17: UI/UX + Frontend: user flow, wireframe/prototype, design system, giao diện responsive và tích hợp API phía người dùng. | C17: Prototype; source frontend; UI checklist | D17: Tuần 2-7 | E17: SV3 | F17: Giao diện nhất quán, dễ dùng, xử lý lỗi và trạng thái
A18: SV4 | B18: Backend/API + DevOps: kiến trúc, API, xác thực/phân quyền, business logic, CI/CD, môi trường và triển khai. | C18: API spec; source backend; pipeline/deploy guide | D18: Tuần 2-8 | E18: SV4 | F18: API có validation, error handling, security cơ bản
A19: SV5 | B19: Database + QA/Tester: mô hình dữ liệu, migration/seed, truy vấn/báo cáo, test plan, test case, defect log và kiểm thử hồi quy. | C19: ERD; data dictionary; test report; defect log | D19: Tuần 2-8 | E19: SV5 | F19: CSDL chuẩn hóa hợp lý; test bao phủ yêu cầu lõi
A20: 3. HỒ SƠ QUẢN LÝ DỰ ÁN BẮT BUỘC
A21: Tích hợp dự án | B21: Project Charter; mục tiêu SMART; Project Management Plan; baseline; change request/log; biên bản đóng dự án và lessons learned. | C21: 01 bộ hồ sơ tích hợp có phiên bản | D21: Tuần 1-8 | E21: PM | F21: Mọi thay đổi phạm vi/tiến độ phải có lý do, tác động và quyết định
A22: Quản lý phạm vi | B22: Stakeholder needs, SRS/user story, scope statement, in/out scope, WBS, WBS dictionary, requirement traceability và nghiệm thu. | C22: SRS + WBS + ma trận truy vết | D22: Tuần 1-2 | E22: BA/PO + PM | F22: 100% yêu cầu ưu tiên cao có acceptance criteria
A23: Quản lý thời gian | B23: Danh sách công việc, phụ thuộc, ước lượng, Gantt/PERT, critical path, milestone, baseline và cập nhật planned-versus-actual mỗi tuần. | C23: Gantt có người phụ trách, ngày bắt đầu/kết thúc, % hoàn thành | D23: Tuần 1-8 | E23: PM | F23: Không để công việc quá 5 ngày mà không có đầu ra kiểm chứng
A24: Quản lý chi phí | B24: Ước lượng effort theo giờ/người; đơn giá giả định; chi phí cloud, domain, công cụ, thiết bị; budget baseline; actual cost và variance. | C24: Cost estimate + budget + bảng theo dõi chênh lệch | D24: Tuần 2-8 | E24: PM | F24: Nêu rõ giả định; kể cả công cụ miễn phí vẫn ghi chi phí 0 và nguồn
A25: Quản lý chất lượng | B25: Quality plan, Definition of Done, coding convention, review checklist, test strategy, tiêu chí hiệu năng/bảo mật cơ bản, defect và corrective action. | C25: Quality plan + test plan + defect log | D25: Tuần 2-8 | E25: QA + cả nhóm | F25: Không còn lỗi Critical/High chưa xử lý khi bảo vệ
A26: Quản lý nhân sự | B26: RACI, kỹ năng/năng lực, capacity, phân bổ công việc, timesheet, peer review, kế hoạch thay thế và xử lý xung đột. | C26: RACI + workload/timesheet + đánh giá chéo | D26: Tuần 1-8 | E26: PM | F26: Khối lượng hợp lý; mỗi thành viên có đầu ra độc lập
A27: Quản lý truyền thông | B27: Stakeholder register, communication matrix, lịch họp, kênh trao đổi, weekly status, meeting minutes, quyết định và escalation. | C27: Biên bản họp hàng tuần + status report | D27: Hàng tuần | E27: PM/Thư ký luân phiên | F27: Ít nhất 01 cuộc họp nhóm/tuần; quyết định quan trọng được ghi nhận
A28: Quản lý rủi ro | B28: Risk register tối thiểu 10 rủi ro; xác suất, tác động, điểm P×I, owner, trigger, response, contingency và cập nhật trạng thái. | C28: Risk matrix + risk register | D28: Tuần 2-8 | E28: PM + owner | F28: Có rủi ro kỹ thuật, yêu cầu, tiến độ, nhân sự, dữ liệu và triển khai
A29: Quản lý mua sắm | B29: Make-or-buy; danh sách cloud/API/domain/license/thiết bị; tiêu chí chọn nhà cung cấp; ngân sách; điều khoản sử dụng và phương án thay thế. | C29: Procurement plan; supplier/tool evaluation | D29: Tuần 3-6 | E29: PM + DevOps | F29: Nếu không mua vẫn phải phân tích quyết định dùng giải pháp miễn phí/mã nguồn mở
A30: Giám sát và kiểm soát | B30: Backlog/board, planned vs actual, milestone review, KPI tiến độ/chất lượng, issue log, change control và hành động khắc phục. | C30: Ảnh/export board + báo cáo tuần + issue/change log | D30: Hàng tuần | E30: PM + cả nhóm | F30: Báo cáo trung thực; chênh lệch phải có nguyên nhân và kế hoạch xử lý
A31: Tóm tắt hồ sơ | B31: Bắt buộc: Charter/PMP; SRS + scope/WBS; Gantt/baseline; effort-cost budget; RACI/timesheet; quality-test-defect; communication/minutes; risk register; procurement; change log; closure/lessons learned. | C31: Nộp chung trong thư mục /docs của repository | D31: Tuần 8 | E31: Cả nhóm | F31: Hồ sơ có phiên bản, ngày cập nhật và người chịu trách nhiệm
A32: 4. TIẾN ĐỘ 8 TUẦN - 9 BUỔI
A33: Mốc chung | B33: Tuần 1: 07.09–13.09.2026; Tuần 2: 14.09–20.09.2026; Tuần 3: 21.09–27.09.2026; Tuần 4: 28.09–04.10.2026; Tuần 5: 05.10–11.10.2026; Tuần 6: 12.10–18.10.2026; Tuần 7: 19.10–25.10.2026; Tuần 8: 26.10–01.11.2026. | C33: Buổi 1-8: hướng dẫn/kiểm tra theo tuần; Buổi 9: bảo vệ cuối kỳ trong Tuần 8 theo lịch GV | D33: 07.09-01.11.2026 | E33: GV + các nhóm | F33: Nộp đúng mốc; trễ phải có change request được duyệt | G33: NỘI DUNG THẢO LUẬN / BÀI ĐĂNG NHÓM
A34: Tuần 1 / Buổi 1 | B34: Khởi động, chọn đề tài, khảo sát, Charter, stakeholder, phân vai, scope và backlog ban đầu. | C34: Phiếu đăng ký + Charter + RACI + backlog | D34: 13.09.2026 | E34: PM/BA | F34: Gate 1: đề tài và phạm vi được GV duyệt | G34: THẢO LUẬN NHÓM – BUỔI 1: KHỞI ĐỘNG DỰ ÁN Mỗi nhóm tạo 01 bài đăng trước 23:59 ngày 13.09.2026, gồm: 1. Mã và tên đề tài; vấn đề cần giải quyết; đối tượng sử dụng chính. 2. Danh sách 5 thành viên, nhóm trưởng và vai trò dự kiến của từng SV. 3. Mục tiêu SMART; 2–4 quy trình nghiệp vụ lõi; phạm vi trong và ngoài dự án. 4. Công nghệ dự kiến, nguồn dữ liệu, khó khăn và rủi ro ban đầu. 5. Kế hoạch công việc Tuần 1 và liên kết thư mục/repository của nhóm. Minh chứng đính kèm: Phiếu đăng ký đề tài, Project Charter v0.1, RACI và backlog ban đầu. Yêu cầu tương tác: mỗi thành viên phản hồi ít nhất 01 ý kiến trong bài nhóm; nhóm góp ý cho ít nhất 01 nhóm khác. GV phản hồi và duyệt đề tài/phạm vi trực tiếp trên bài đăng.
A35: Tuần 2 / Buổi 2 | B35: Hoàn tất SRS, use case/user story, WBS, Gantt baseline, effort/cost, risk register v1, UI flow và ERD v1. | C35: SRS v1 + WBS/Gantt + budget + risk v1 + prototype/ERD | D35: 20.09.2026 | E35: Cả nhóm | F35: Gate 2: kế hoạch khả thi và truy vết yêu cầu | G35: THẢO LUẬN NHÓM – BUỔI 2: PHẠM VI VÀ KẾ HOẠCH Nhóm trình bày vấn đề, stakeholder, mục tiêu SMART, phạm vi in-scope/out-of-scope và 8–14 use case/user story ưu tiên. Đính kèm: SRS v1, WBS, Gantt baseline, dự toán effort/chi phí, Risk Register v1, UI flow và ERD v1. Câu hỏi phản biện: Phạm vi nào có nguy cơ vượt quá 8 tuần? Nhóm sẽ cắt giảm chức năng nào trước?
A36: Tuần 3 / Buổi 3 | B36: Kiến trúc, database, API contract, môi trường, đăng nhập/RBAC và CRUD lõi; procurement decision. | C36: Architecture/API spec + schema + demo increment 1 | D36: 27.09.2026 | E36: Dev team | F36: Demo được luồng đăng nhập và dữ liệu lõi | G36: THẢO LUẬN NHÓM – BUỔI 3: KIẾN TRÚC VÀ TRIỂN KHAI LÕI Nhóm mô tả kiến trúc hệ thống, công nghệ, mô hình dữ liệu, API contract, xác thực/phân quyền và quy trình nghiệp vụ lõi đầu tiên. Đính kèm: sơ đồ kiến trúc, ERD/schema, API spec, ảnh/video demo đăng nhập và CRUD lõi. Câu hỏi phản biện: Quyết định kỹ thuật nào có rủi ro cao nhất và phương án thay thế là gì?
A37: Tuần 4 / Buổi 4 | B37: Hoàn thiện 40-50% nghiệp vụ; cập nhật tiến độ, chi phí, rủi ro; test sớm; thuyết trình giữa kỳ. | C37: Demo increment 2 + status report + slide giữa kỳ | D37: 04.10.2026 | E37: Cả nhóm | F37: Mốc >=50% kế hoạch; bài nhóm thuyết trình 10% | G37: THẢO LUẬN NHÓM – BUỔI 4: BÁO CÁO GIỮA KỲ Nhóm báo cáo mức độ hoàn thành so với baseline, chức năng đã demo, tiến độ từng thành viên, chi phí thực tế, lỗi và rủi ro hiện tại. Đính kèm: demo increment 2, status report, Gantt planned-versus-actual và slide giữa kỳ. Yêu cầu: nêu rõ nguyên nhân chênh lệch và hành động để đạt tối thiểu 50% kế hoạch.
A38: Tuần 5 / Buổi 5 | B38: Hoàn thiện 70% nghiệp vụ, báo cáo/dashboard, tích hợp dịch vụ; quality review và change control. | C38: Demo increment 3 + quality report + change log | D38: 11.10.2026 | E38: Cả nhóm | F38: Các thay đổi đã được đánh giá tác động | G38: THẢO LUẬN NHÓM – BUỔI 5: CHẤT LƯỢNG VÀ THAY ĐỔI Nhóm cập nhật tiến độ 70%, dashboard/báo cáo, tích hợp dịch vụ và các yêu cầu thay đổi phát sinh. Đính kèm: demo increment 3, quality checklist, change log, test case mẫu và kết quả review. Câu hỏi phản biện: Thay đổi nào nên chấp nhận hoặc từ chối dựa trên tác động phạm vi, thời gian và chất lượng?
A39: Tuần 6 / Buổi 6 | B39: Feature complete; unit/integration/system test; sửa lỗi; kiểm tra bảo mật/hiệu năng cơ bản; cập nhật tài liệu. | C39: Release candidate 1 + test/defect report | D39: 18.10.2026 | E39: QA + Dev | F39: 100% chức năng ưu tiên cao đã code; không còn lỗi Critical | G39: THẢO LUẬN NHÓM – BUỔI 6: KIỂM THỬ VÀ QUẢN LÝ LỖI Nhóm báo cáo trạng thái feature complete, phạm vi unit/integration/system test, số lượng test pass/fail và lỗi theo mức độ. Đính kèm: Release Candidate 1, test report, defect log và bằng chứng sửa lỗi. Yêu cầu: phân công owner, thời hạn xử lý và không để lỗi Critical chưa có phương án.
A40: Tuần 7 / Buổi 7 | B40: UAT, regression, deploy demo, dữ liệu mẫu, backup/restore, tối ưu UX; chốt báo cáo và video. | C40: Release candidate 2 + URL demo + UAT + draft report | D40: 25.10.2026 | E40: Cả nhóm | F40: Gate 3: sẵn sàng bảo vệ | G40: THẢO LUẬN NHÓM – BUỔI 7: UAT VÀ SẴN SÀNG BẢO VỆ Nhóm trình bày kết quả UAT, regression, deploy demo, dữ liệu mẫu, tài khoản theo vai trò, backup/restore và tình trạng tài liệu. Đính kèm: URL demo, Release Candidate 2, UAT report, draft báo cáo và kịch bản demo. Câu hỏi phản biện: Nếu hệ thống lỗi khi bảo vệ, nhóm có phương án dự phòng nào?
A41: Tuần 8 / Buổi 8-9 | B41: Đóng dự án; nộp đủ hồ sơ/source; demo; trình bày; phản biện/vấn đáp cá nhân; lessons learned. | C41: Final release + hồ sơ + slide + video + biên bản đóng dự án | D41: 26.10-01.11.2026 | E41: Cả nhóm | F41: Mỗi SV trả lời phần việc và kiến thức quản lý dự án | G41: THẢO LUẬN NHÓM – BUỔI 8–9: ĐÓNG DỰ ÁN VÀ BẢO VỆ Nhóm tổng kết kết quả so với mục tiêu, phạm vi baseline, tiến độ, chi phí, chất lượng, rủi ro, đóng góp từng thành viên và lessons learned. Đính kèm: Final release, repository, hồ sơ /docs, báo cáo, slide, video, biên bản đóng dự án và minh chứng cá nhân. Mỗi SV đăng phần việc chính, liên kết commit/ticket và 2 bài học rút ra; chuẩn bị trả lời vấn đáp cá nhân.
...
